Workbook
Name acc_bodies: Accreditation_Body[]
Name acc_bodies: Accreditation_Body[name]
Name courses_list: Courses[name]
Name faculties_list: Faculties!$C$2:$C$8
Name pro_types: Program_Types[name]
Name programs_list: Table15[name]
Name rooms_list: Table22[name]
Name session_type_list: Table1[name]
Name staff_list: Staff!$C$2:$C$14

Sheet Faculties
A1: id | B1: code | C1: name | D1: short_name | E1: description | F1: dean_name | G1: contact_email | H1: status | I1: display_label
A2: =( MAX($A$1:A1)+1) -> 1 | B2: FULLTIMEQU | C2: Full time qualification | E2: Full time qualification | H2: active | I2: ="("&A2&") - "&C2 -> (1) - Full time qualification
A3: =( MAX($A$1:A2)+1) -> 2 | B3: PARTTIMEQU | C3: Part Time Qualification | E3: Part Time Qualification | H3: active | I3: ="("&A3&") - "&C3 -> (2) - Part Time Qualification
A4: =( MAX($A$1:A3)+1) -> 3 | B4: SHORTCOURS | C4: Short Courses | E4: Short Courses | H4: active | I4: ="("&A4&") - "&C4 -> (3) - Short Courses
A5: =( MAX($A$1:A4)+1) -> 4 | B5: ARPLTRADET | C5: ARPL-Trade Test | E5: ARPL-Trade Test | H5: active | I5: ="("&A5&") - "&C5 -> (4) - ARPL-Trade Test
A6: =( MAX($A$1:A5)+1) -> 5 | B6: HOSPITALITY | C6: Hospitality Faculty | D6: Hospitality | E6: Faculty for Hospitality and Culinary Arts Programs | H6: active | I6: ="("&A6&") - "&C6 -> (5) - Hospitality Faculty
A7: =( MAX($A$1:A6)+1) -> 6 | B7: ADFADFADF | C7: SADFVD323232323FGDSFG | D7: FBXVBV XVB | E7: CXVB XCVB CXVBCXVBCXB | H7: active | I7: ="("&A7&") - "&C7 -> (6) - SADFVD323232323FGDSFG
A8: =( MAX($A$1:A7)+1) -> 7 | B8: 89j89h9 | C8: 98uh98h | D8: 9u8h89h | E8: uwebx9weubxwe9u | H8: active | I8: ="("&A8&") - "&C8 -> (7) - 98uh98h

Sheet Programs
A1: id | B1: Faculty_Name_ignore | C1: faculty_id | D1: program_type_name_ignore | E1: program_type_id | F1: code | G1: name | H1: short_name | I1: nqf_level | J1: total_credits | K1: duration_years | L1: accrediting_body_ignore | M1: accreditation_body_id | N1: status
A2: =( MAX($A$1:A1)+1) -> 1 | B2: Full time qualification | C2: =IF(B2="", "", _xlfn.XLOOKUP(B2, Faculties!C:C, Faculties!A:A)) -> 1 | D2: Diploma | E2: =IF(D2="", "", _xlfn.XLOOKUP(D2, Program_Types!B:B, Program_Types!A:A)) -> 1 | F2: HOS-1 | G2: Hospitality Management | L2: International | M2: =IF(L2="", "", _xlfn.XLOOKUP(L2, Accreditation_Bodies!B:B, Accreditation_Bodies!A:A)) -> 3 | N2: active
A3: =( MAX($A$1:A2)+1) -> 2 | B3: Full time qualification | C3: =IF(B3="", "", _xlfn.XLOOKUP(B3, Faculties!C:C, Faculties!A:A)) -> 1 | D3: Diploma | E3: =IF(D3="", "", _xlfn.XLOOKUP(D3, Program_Types!B:B, Program_Types!A:A)) -> 1 | F3: FOO-1 | G3: Food Preparation and Culinary Arts | L3: QCTO | M3: =IF(L3="", "", _xlfn.XLOOKUP(L3, Accreditation_Bodies!B:B, Accreditation_Bodies!A:A)) -> 1 | N3: active
A4: =( MAX($A$1:A3)+1) -> 3 | B4: Full time qualification | C4: =IF(B4="", "", _xlfn.XLOOKUP(B4, Faculties!C:C, Faculties!A:A)) -> 1 | D4: Diploma | E4: =IF(D4="", "", _xlfn.XLOOKUP(D4, Program_Types!B:B, Program_Types!A:A)) -> 1 | F4: FOO-1-1 | G4: Food and Beverage Service | L4: QCTO | M4: =IF(L4="", "", _xlfn.XLOOKUP(L4, Accreditation_Bodies!B:B, Accreditation_Bodies!A:A)) -> 1 | N4: active
A5: =( MAX($A$1:A4)+1) -> 4 | B5: Full time qualification | C5: =IF(B5="", "", _xlfn.XLOOKUP(B5, Faculties!C:C, Faculties!A:A)) -> 1 | D5: Diploma | E5: =IF(D5="", "", _xlfn.XLOOKUP(D5, Program_Types!B:B, Program_Types!A:A)) -> 1 | F5: HOU-1 | G5: Housekeeping Service | L5: QCTO | M5: =IF(L5="", "", _xlfn.XLOOKUP(L5, Accreditation_Bodies!B:B, Accreditation_Bodies!A:A)) -> 1 | N5: active
A6: =( MAX($A$1:A5)+1) -> 5 | B6: Full time qualification | C6: =IF(B6="", "", _xlfn.XLOOKUP(B6, Faculties!C:C, Faculties!A:A)) -> 1 | D6: Diploma | E6: =IF(D6="", "", _xlfn.XLOOKUP(D6, Program_Types!B:B, Program_Types!A:A)) -> 1 | F6: CUL-1 | G6: Culinary Arts and Supervision | L6: QCTO | M6: =IF(L6="", "", _xlfn.XLOOKUP(L6, Accreditation_Bodies!B:B, Accreditation_Bodies!A:A)) -> 1 | N6: active
A7: =( MAX($A$1:A2)+1) -> 2 | B7: Full time qualification | C7: =IF(B7="", "", _xlfn.XLOOKUP(B7, Faculties!C:C, Faculties!A:A)) -> 1 | D7: Diploma | E7: =IF(D7="", "", _xlfn.XLOOKUP(D7, Program_Types!B:B, Program_Types!A:A)) -> 1 | F7: PAT-1 | G7: Patisserie and Confectionery | L7: QCTO | M7: =IF(L7="", "", _xlfn.XLOOKUP(L7, Accreditation_Bodies!B:B, Accreditation_Bodies!A:A)) -> 1 | N7: active
A8: =( MAX($A$1:A7)+1) -> 6 | B8: Full time qualification | C8: =IF(B8="", "", _xlfn.XLOOKUP(B8, Faculties!C:C, Faculties!A:A)) -> 1 | D8: Diploma | E8: =IF(D8="", "", _xlfn.XLOOKUP(D8, Program_Types!B:B, Program_Types!A:A)) -> 1 | F8: BAR-1 | G8: Barista | L8: QCTO | M8: =IF(L8="", "", _xlfn.XLOOKUP(L8, Accreditation_Bodies!B:B, Accreditation_Bodies!A:A)) -> 1 | N8: active
A9: =( MAX($A$1:A8)+1) -> 7 | B9: Part Time Qualification | C9: =IF(B9="", "", _xlfn.XLOOKUP(B9, Faculties!C:C, Faculties!A:A)) -> 2 | D9: Diploma | E9: =IF(D9="", "", _xlfn.XLOOKUP(D9, Program_Types!B:B, Program_Types!A:A)) -> 1 | F9: HOS-2 | G9: Hospitality Management (Part Time) | L9: QCTO | M9: =IF(L9="", "", _xlfn.XLOOKUP(L9, Accreditation_Bodies!B:B, Accreditation_Bodies!A:A)) -> 1 | N9: active
A10: =( MAX($A$1:A9)+1) -> 8 | B10: Short Courses | C10: =IF(B10="", "", _xlfn.XLOOKUP(B10, Faculties!C:C, Faculties!A:A)) -> 3 | D10: Diploma | E10: =IF(D10="", "", _xlfn.XLOOKUP(D10, Program_Types!B:B, Program_Types!A:A)) -> 1 | F10: COO-3 | G10: Cooking Courses | L10: QCTO | M10: =IF(L10="", "", _xlfn.XLOOKUP(L10, Accreditation_Bodies!B:B, Accreditation_Bodies!A:A)) -> 1 | N10: active
A11: =( MAX($A$1:A2)+1) -> 2 | B11: Short Courses | C11: =IF(B11="", "", _xlfn.XLOOKUP(B11, Faculties!C:C, Faculties!A:A)) -> 3 | D11: Diploma | E11: =IF(D11="", "", _xlfn.XLOOKUP(D11, Program_Types!B:B, Program_Types!A:A)) -> 1 | F11: CAT-3 | G11: Catering Courses | L11: CATHSETA | M11: =IF(L11="", "", _xlfn.XLOOKUP(L11, Accreditation_Bodies!B:B, Accreditation_Bodies!A:A)) -> 2 | N11: active
A12: =( MAX($A$1:A11)+1) -> 9 | B12: Short Courses | C12: =IF(B12="", "", _xlfn.XLOOKUP(B12, Faculties!C:C, Faculties!A:A)) -> 3 | D12: Short Course | E12: =IF(D12="", "", _xlfn.XLOOKUP(D12, Program_Types!B:B, Program_Types!A:A)) -> 7 | F12: BAK-3 | G12: Baking Courses | L12: QCTO | M12: =IF(L12="", "", _xlfn.XLOOKUP(L12, Accreditation_Bodies!B:B, Accreditation_Bodies!A:A)) -> 1 | N12: active
A13: =( MAX($A$1:A2)+1) -> 2 | B13: Short Courses | C13: =IF(B13="", "", _xlfn.XLOOKUP(B13, Faculties!C:C, Faculties!A:A)) -> 3 | D13: Short Course | E13: =IF(D13="", "", _xlfn.XLOOKUP(D13, Program_Types!B:B, Program_Types!A:A)) -> 7 | F13: CON-3 | G13: Confectionary Course | L13: QCTO | M13: =IF(L13="", "", _xlfn.XLOOKUP(L13, Accreditation_Bodies!B:B, Accreditation_Bodies!A:A)) -> 1 | N13: active
A14: =( MAX($A$1:A13)+1) -> 10 | B14: ARPL-Trade Test | C14: =IF(B14="", "", _xlfn.XLOOKUP(B14, Faculties!C:C, Faculties!A:A)) -> 4 | D14: Short Course | E14: =IF(D14="", "", _xlfn.XLOOKUP(D14, Program_Types!B:B, Program_Types!A:A)) -> 7 | F14: TRA-4 | G14: Trade test - Artisan Chef | L14: QCTO | M14: =IF(L14="", "", _xlfn.XLOOKUP(L14, Accreditation_Bodies!B:B, Accreditation_Bodies!A:A)) -> 1 | N14: active
A15: =( MAX($A$1:A14)+1) -> 11 | B15: Hospitality Faculty | C15: =IF(B15="", "", _xlfn.XLOOKUP(B15, Faculties!C:C, Faculties!A:A)) -> 5 | D15: Diploma | E15: =IF(D15="", "", _xlfn.XLOOKUP(D15, Program_Types!B:B, Program_Types!A:A)) -> 1 | F15: OCHEF | G15: Artisan Chef Program | L15: QCTO | M15: =IF(L15="", "", _xlfn.XLOOKUP(L15, Accreditation_Bodies!B:B, Accreditation_Bodies!A:A)) -> 1 | N15: active
A16: =( MAX($A$1:A15)+1) -> 12 | B16: SADFVD323232323FGDSFG | C16: =IF(B16="", "", _xlfn.XLOOKUP(B16, Faculties!C:C, Faculties!A:A)) -> 6 | D16: Honours Degree | E16: =IF(D16="", "", _xlfn.XLOOKUP(D16, Program_Types!B:B, Program_Types!A:A)) -> 3 | F16: dsvfsf | G16: dvsdfvdsfvdz | L16: International | M16: =IF(L16="", "", _xlfn.XLOOKUP(L16, Accreditation_Bodies!B:B, Accreditation_Bodies!A:A)) -> 3 | N16: active
A17: =( MAX($A$1:A16)+1) -> 13 | B17: 98uh98h | C17: =IF(B17="", "", _xlfn.XLOOKUP(B17, Faculties!C:C, Faculties!A:A)) -> 7 | D17: Bachelor's Degree | E17: =IF(D17="", "", _xlfn.XLOOKUP(D17, Program_Types!B:B, Program_Types!A:A)) -> 2 | F17: mio | G17: uionbi8bo98 | L17: CATHSETA | M17: =IF(L17="", "", _xlfn.XLOOKUP(L17, Accreditation_Bodies!B:B, Accreditation_Bodies!A:A)) -> 2 | N17: active

Sheet Courses
A1: id | B1: program_name_ignore | C1: program_id | D1: level_id | E1: code | F1: name | G1: nqf_level | H1: credits | I1: contact_hours | J1: category_id | K1: is_required | L1: status
A2: =MAX($A$1:A1)+1 -> 1 | B2: Hospitality Management | C2: =IF($B2="", "", _xlfn.XLOOKUP($B2, Programs!G:G, Programs!A:A)) -> 1 | E2: HOS01001 | F2: Diploma in Introduction to the Hospitality Industry | G2: 5 | H2: 120 | K2: 1 | L2: active | N2: =IF(B2="", "", _xlfn.XLOOKUP(B2, Programs!G:G, Programs!A:A)) -> 1
A3: =MAX($A$1:A2)+1 -> 2 | B3: Food Preparation and Culinary Arts | C3: =IF($B3="", "", _xlfn.XLOOKUP($B3, Programs!G:G, Programs!A:A)) -> 2 | E3: FOO02001 | F3: Advanced Diploma in Culinary Arts and Supervision | G3: 6 | H3: 120 | K3: 1 | L3: active
A4: =MAX($A$1:A3)+1 -> 3 | B4: Food Preparation and Culinary Arts | C4: =IF($B4="", "", _xlfn.XLOOKUP($B4, Programs!G:G, Programs!A:A)) -> 2 | E4: FOO02002 | F4: Diploma Patisserie and Confectionery | G4: 5 | H4: 120 | K4: 1 | L4: active
A5: =MAX($A$1:A4)+1 -> 4 | B5: Food and Beverage Service | C5: =IF($B5="", "", _xlfn.XLOOKUP($B5, Programs!G:G, Programs!A:A)) -> 3 | E5: FOO03001 | F5: Diploma Food and Beverage Service | G5: 5 | H5: 120 | K5: 1 | L5: active
A6: =MAX($A$1:A5)+1 -> 5 | B6: Housekeeping Service | C6: =IF($B6="", "", _xlfn.XLOOKUP($B6, Programs!G:G, Programs!A:A)) -> 4 | E6: HOU04001 | F6: Diploma in Housekeeping Service | G6: 5 | H6: 120 | K6: 1 | L6: active
A7: =MAX($A$1:A6)+1 -> 6 | B7: Housekeeping Service | C7: =IF($B7="", "", _xlfn.XLOOKUP($B7, Programs!G:G, Programs!A:A)) -> 4 | E7: HOU04002 | F7: Advanced Diploma in Housekeeping Service | G7: 6 | H7: 120 | K7: 1 | L7: active
A8: =MAX($A$1:A7)+1 -> 7 | B8: Barista | C8: =IF($B8="", "", _xlfn.XLOOKUP($B8, Programs!G:G, Programs!A:A)) -> 6 | E8: BAR07001 | F8: Advanced Diploma in Barista | G8: 5 | H8: 60 | K8: 1 | L8: active
A9: =MAX($A$1:A8)+1 -> 8 | B9: Cooking Courses | C9: =IF($B9="", "", _xlfn.XLOOKUP($B9, Programs!G:G, Programs!A:A)) -> 8 | E9: COO09001 | F9: Basic Cooking Course | G9: 3 | H9: 8 | K9: 1 | L9: active
A10: =MAX($A$1:A9)+1 -> 9 | B10: Cooking Courses | C10: =IF($B10="", "", _xlfn.XLOOKUP($B10, Programs!G:G, Programs!A:A)) -> 8 | E10: COO09002 | F10: Advance Cooking Course | G10: 4 | H10: 12 | K10: 1 | L10: active
A11: =MAX($A$1:A10)+1 -> 10 | B11: Catering Courses | C11: =IF($B11="", "", _xlfn.XLOOKUP($B11, Programs!G:G, Programs!A:A)) -> 2 | E11: CAT10001 | F11: Catering Fundamentals | G11: 3 | H11: 8 | K11: 1 | L11: active
A12: =MAX($A$1:A11)+1 -> 11 | B12: Baking Courses | C12: =IF($B12="", "", _xlfn.XLOOKUP($B12, Programs!G:G, Programs!A:A)) -> 9 | E12: BAK11001 | F12: Basic Baking Course (Variety of doughs) | G12: 3 | H12: 8 | K12: 1 | L12: active
A13: =MAX($A$1:A12)+1 -> 12 | B13: Baking Courses | C13: =IF($B13="", "", _xlfn.XLOOKUP($B13, Programs!G:G, Programs!A:A)) -> 9 | E13: BAK11002 | F13: Advanced Baking Course | G13: 4 | H13: 12 | K13: 1 | L13: active
A14: =MAX($A$1:A13)+1 -> 13 | B14: Baking Courses | C14: =IF($B14="", "", _xlfn.XLOOKUP($B14, Programs!G:G, Programs!A:A)) -> 9 | E14: BAK11003 | F14: One day Biscuit Making | G14: 3 | H14: 1 | K14: 1 | L14: active
... A21: =MAX($A$1:A20)+1 -> 20 | B21: uionbi8bo98 | C21: =IF($B21="", "", _xlfn.XLOOKUP($B21, Programs!G:G, Programs!A:A)) -> 13 | E21: 3g5g5g | F21: g4ttggte | G21: 34 | H21: 345 | K21: 1 | L21: active
A22: =MAX($A$1:A21)+1 -> 21 | B22: dvsdfvdsfvdz | C22: =IF($B22="", "", _xlfn.XLOOKUP($B22, Programs!G:G, Programs!A:A)) -> 12 | E22: 889h99 | F22: 90i0909i | G22: 89 | K22: 1 | L22: active

Sheet Course_Schedules
A1: id | B1: Course_Name_ignore | C1: course_id | D1: Lecture_name_ignore | E1: lecturer_id | F1: days | G1: start_time | H1: end_time | I1: day_hours | J1: session_type | K1: Room_Name_Ignore | L1: Room_Id | M1: is_active
A2: =MAX($A$1:A1)+1 -> 1 | B2: Diploma in Introduction to the Hospitality Industry | C2: =IF(B2="", "", _xlfn.XLOOKUP(B2, 'Courses'!F:F, 'Courses'!A:A)) -> 1 | D2: Estelle | E2: =IF(D2="", "", _xlfn.XLOOKUP(D2, Staff!C:C, Staff!A:A)) -> 3 | F2: Monday, Wednesday | G2: 0.64166667 | H2: 0.41666667 | I2: =MOD(H2-G2,1) -> 0.775 | J2: Lecture | K2: Classroom 2 | L2: =IF(K2="", "", _xlfn.XLOOKUP(K2, wp_nds_rooms!C:C, wp_nds_rooms!A:A)) -> 3 | M2: 1
A3: =MAX($A$1:A2)+1 -> 2 | B3: Advanced Diploma in Culinary Arts and Supervision | C3: =IF(B3="", "", _xlfn.XLOOKUP(B3, 'Courses'!F:F, 'Courses'!A:A)) -> 2 | D3: Mpuse | E3: =IF(D3="", "", _xlfn.XLOOKUP(D3, Staff!C:C, Staff!A:A)) -> 8 | F3: Monday, Wednesday | G3: 0.64236111 | H3: 0.41666667 | I3: =MOD(H3-G3,1) -> 0.77430556 | J3: Lecture | K3: Classroom 3 | L3: =IF(K3="", "", _xlfn.XLOOKUP(K3, wp_nds_rooms!C:C, wp_nds_rooms!A:A)) -> 4 | M3: 1
A4: =MAX($A$1:A3)+1 -> 3 | B4: Advanced Diploma in Culinary Arts and Supervision | C4: =IF(B4="", "", _xlfn.XLOOKUP(B4, 'Courses'!F:F, 'Courses'!A:A)) -> 2 | D4: Estelle | E4: =IF(D4="", "", _xlfn.XLOOKUP(D4, Staff!C:C, Staff!A:A)) -> 3 | F4: Friday | G4: 0.58333333 | H4: 0.70833333 | I4: =MOD(H4-G4,1) -> 0.125 | J4: Assessment | K4: Kitchen 1 - Main Training Kitchen | L4: =IF(K4="", "", _xlfn.XLOOKUP(K4, wp_nds_rooms!C:C, wp_nds_rooms!A:A)) -> 5 | M4: 1
A5: =MAX($A$1:A4)+1 -> 4 | B5: Advanced Diploma in Culinary Arts and Supervision | C5: =IF(B5="", "", _xlfn.XLOOKUP(B5, 'Courses'!F:F, 'Courses'!A:A)) -> 2 | D5: Nseya | E5: =IF(D5="", "", _xlfn.XLOOKUP(D5, Staff!C:C, Staff!A:A)) -> 7 | F5: Friday | G5: 0.58333333 | H5: 0.70833333 | I5: =MOD(H5-G5,1) -> 0.125 | J5: Assessment | K5: Classroom 2 | L5: =IF(K5="", "", _xlfn.XLOOKUP(K5, wp_nds_rooms!C:C, wp_nds_rooms!A:A)) -> 3 | M5: 1
A6: =MAX($A$1:A5)+1 -> 5 | B6: Diploma Patisserie and Confectionery | C6: =IF(B6="", "", _xlfn.XLOOKUP(B6, 'Courses'!F:F, 'Courses'!A:A)) -> 3 | D6: Nseya | E6: =IF(D6="", "", _xlfn.XLOOKUP(D6, Staff!C:C, Staff!A:A)) -> 7 | F6: Monday, Wednesday | G6: 0.33333333 | H6: 0.41666667 | I6: =MOD(H6-G6,1) -> 0.083333333 | J6: Lecture | K6: Classroom 2 | L6: =IF(K6="", "", _xlfn.XLOOKUP(K6, wp_nds_rooms!C:C, wp_nds_rooms!A:A)) -> 3 | M6: 1
A7: =MAX($A$1:A6)+1 -> 6 | B7: Diploma Food and Beverage Service | C7: =IF(B7="", "", _xlfn.XLOOKUP(B7, 'Courses'!F:F, 'Courses'!A:A)) -> 4 | D7: Lwethu | E7: =IF(D7="", "", _xlfn.XLOOKUP(D7, Staff!C:C, Staff!A:A)) -> 6 | F7: Monday, Wednesday | G7: 0.33333333 | H7: 0.41666667 | I7: =MOD(H7-G7,1) -> 0.083333333 | J7: Lecture | K7: Main Hall | L7: =IF(K7="", "", _xlfn.XLOOKUP(K7, wp_nds_rooms!C:C, wp_nds_rooms!A:A)) -> 1 | M7: 1
A8: =MAX($A$1:A7)+1 -> 7 | B8: Diploma in Housekeeping Service | C8: =IF(B8="", "", _xlfn.XLOOKUP(B8, 'Courses'!F:F, 'Courses'!A:A)) -> 5 | D8: Nseya | E8: =IF(D8="", "", _xlfn.XLOOKUP(D8, Staff!C:C, Staff!A:A)) -> 7 | F8: Monday, Wednesday | G8: 0.33333333 | H8: 0.41666667 | I8: =MOD(H8-G8,1) -> 0.083333333 | J8: Lecture | K8: Classroom 3 | L8: =IF(K8="", "", _xlfn.XLOOKUP(K8, wp_nds_rooms!C:C, wp_nds_rooms!A:A)) -> 4 | M8: 1
A9: =MAX($A$1:A8)+1 -> 8 | B9: Advanced Diploma in Housekeeping Service | C9: =IF(B9="", "", _xlfn.XLOOKUP(B9, 'Courses'!F:F, 'Courses'!A:A)) -> 6 | D9: Nseya | E9: =IF(D9="", "", _xlfn.XLOOKUP(D9, Staff!C:C, Staff!A:A)) -> 7 | F9: Monday, Wednesday | G9: 0.33333333 | H9: 0.41666667 | I9: =MOD(H9-G9,1) -> 0.083333333 | J9: Lecture | K9: Main Hall | L9: =IF(K9="", "", _xlfn.XLOOKUP(K9, wp_nds_rooms!C:C, wp_nds_rooms!A:A)) -> 1 | M9: 1
A10: =MAX($A$1:A9)+1 -> 9 | B10: Advanced Diploma in Barista | C10: =IF(B10="", "", _xlfn.XLOOKUP(B10, 'Courses'!F:F, 'Courses'!A:A)) -> 7 | D10: Nseya | E10: =IF(D10="", "", _xlfn.XLOOKUP(D10, Staff!C:C, Staff!A:A)) -> 7 | F10: Monday, Wednesday | G10: 0.33333333 | H10: 0.41666667 | I10: =MOD(H10-G10,1) -> 0.083333333 | J10: Lecture | K10: Kitchen 1 - Main Training Kitchen | L10: =IF(K10="", "", _xlfn.XLOOKUP(K10, wp_nds_rooms!C:C, wp_nds_rooms!A:A)) -> 5 | M10: 1
A11: =MAX($A$1:A10)+1 -> 10 | B11: Basic Cooking Course | C11: =IF(B11="", "", _xlfn.XLOOKUP(B11, 'Courses'!F:F, 'Courses'!A:A)) -> 8 | D11: Nseya | E11: =IF(D11="", "", _xlfn.XLOOKUP(D11, Staff!C:C, Staff!A:A)) -> 7 | F11: Monday, Wednesday | G11: 0.33333333 | H11: 0.5 | I11: =MOD(H11-G11,1) -> 0.16666667 | J11: Lecture | K11: Classroom 1 | L11: =IF(K11="", "", _xlfn.XLOOKUP(K11, wp_nds_rooms!C:C, wp_nds_rooms!A:A)) -> 2 | M11: 1
A12: =MAX($A$1:A11)+1 -> 11 | B12: Basic Cooking Course | C12: =IF(B12="", "", _xlfn.XLOOKUP(B12, 'Courses'!F:F, 'Courses'!A:A)) -> 8 | D12: Nseya | E12: =IF(D12="", "", _xlfn.XLOOKUP(D12, Staff!C:C, Staff!A:A)) -> 7 | F12: Tuesday, Thursday | G12: 0.375 | H12: 0.625 | I12: =MOD(H12-G12,1) -> 0.25 | J12: Practical | K12: Classroom 1 | L12: =IF(K12="", "", _xlfn.XLOOKUP(K12, wp_nds_rooms!C:C, wp_nds_rooms!A:A)) -> 2 | M12: 1
A13: =MAX($A$1:A12)+1 -> 12 | B13: Basic Cooking Course | C13: =IF(B13="", "", _xlfn.XLOOKUP(B13, 'Courses'!F:F, 'Courses'!A:A)) -> 8 | D13: Jacobus | E13: =IF(D13="", "", _xlfn.XLOOKUP(D13, Staff!C:C, Staff!A:A)) -> 5 | F13: Friday | G13: 0.58333333 | H13: 0.70833333 | I13: =MOD(H13-G13,1) -> 0.125 | J13: Assessment | K13: Main Hall | L13: =IF(K13="", "", _xlfn.XLOOKUP(K13, wp_nds_rooms!C:C, wp_nds_rooms!A:A)) -> 1 | M13: 1
... A26: =MAX($A$1:A25)+1 -> 25 | B26: Trade test - Artisan Chef | C26: =IF(B26="", "", _xlfn.XLOOKUP(B26, 'Courses'!F:F, 'Courses'!A:A)) -> 15 | D26: David | E26: =IF(D26="", "", _xlfn.XLOOKUP(D26, Staff!C:C, Staff!A:A)) -> 12 | F26: Friday | G26: 0.58333333 | H26: 0.70833333 | I26: =MOD(H26-G26,1) -> 0.125 | J26: Assessment | K26: Main Hall | L26: =IF(K26="", "", _xlfn.XLOOKUP(K26, wp_nds_rooms!C:C, wp_nds_rooms!A:A)) -> 1 | M26: 1
A27: =MAX($A$1:A26)+1 -> 26 | B27: 2efecfer | C27: =IF(B27="", "", _xlfn.XLOOKUP(B27, 'Courses'!F:F, 'Courses'!A:A)) -> 17 | D27: Irene | E27: =IF(D27="", "", _xlfn.XLOOKUP(D27, Staff!C:C, Staff!A:A)) -> 9 | F27: Monday, Wednesday | G27: 0.45833333 | H27: 0.54166667 | I27: =MOD(H27-G27,1) -> 0.083333333 | J27: Lecture | K27: Kitchen 1 - Main Training Kitchen | L27: =IF(K27="", "", _xlfn.XLOOKUP(K27, wp_nds_rooms!C:C, wp_nds_rooms!A:A)) -> 5

Sheet Session_type
A1: id | B1: name
A2: =MAX($A$1:A1)+1 -> 1 | B2: Lecture
A3: =MAX($A$1:A2)+1 -> 2 | B3: Assessment
A4: =MAX($A$1:A3)+1 -> 3 | B4: Practical
A5: =MAX($A$1:A4)+1 -> 4 | B5: Trade Test
A6: =MAX($A$1:A5)+1 -> 5 | B6: asdasdas

Sheet Staff
A1: id | B1: user_id | C1: first_name | D1: last_name | E1: email | F1: phone | G1: role
A2: =MAX($A$1:A1)+1 -> 1 | B2: 10 | C2: Lebogang | D2: Lekotokoto | E2: Lebogang@ndsacademy.co.za | F2: 111111111 | G2: Lecturer
A3: =MAX($A$1:A2)+1 -> 2 | B3: 12 | C3: Tshepiso | D3: Tunzi | E3: MrsTshepiso@ndsacademy.co.za | F3: 111111112 | G3: Lecturer
A4: =MAX($A$1:A3)+1 -> 3 | B4: 13 | C4: Estelle | D4: Holtzhausen | E4: MrsEstelle@ndsacademy.co.za | F4: 111111113 | G4: Lecturer
A5: =MAX($A$1:A4)+1 -> 4 | B5: 14 | C5: Pontsho | D5: Mogiwa | E5: MrsPontsho@ndsacademy.co.za | F5: 111111114 | G5: Lecturer
A6: =MAX($A$1:A5)+1 -> 5 | B6: 15 | C6: Jacobus | D6: Sutton | E6: MrJacobus@ndsacademy.co.za | F6: 111111115 | G6: Lecturer
A7: =MAX($A$1:A6)+1 -> 6 | B7: 16 | C7: Lwethu | D7: Htlatswayo | E7: MsLwethu@ndsacademy.co.za | F7: 111111116 | G7: Lecturer
A8: =MAX($A$1:A7)+1 -> 7 | B8: 17 | C8: Nseya | D8: Tshitundui | E8: MsNseya@ndsacademy.co.za | F8: 111111117 | G8: Lecturer
A9: =MAX($A$1:A8)+1 -> 8 | B9: 18 | C9: Mpuse | D9: Mnguni | E9: MrsMpuse@ndsacademy.co.za | F9: 111111118 | G9: Lecturer
A10: =MAX($A$1:A9)+1 -> 9 | B10: 19 | C10: Irene | D10: Xaba | E10: MsIrene@ndsacademy.co.za | F10: 111111119 | G10: Lecturer
A11: =MAX($A$1:A10)+1 -> 10 | C11: Thabo | D11: Molefe | E11: MrThabo@ndsacademy.co.za | F11: 111111120 | G11: Head Chef
A12: =MAX($A$1:A11)+1 -> 11 | C12: Sarah | D12: Johnson | E12: MsSarah@ndsacademy.co.za | F12: 111111121 | G12: Administrator
A13: =MAX($A$1:A12)+1 -> 12 | C13: David | D13: Nkomo | E13: MrDavid@ndsacademy.co.za | F13: 111111122 | G13: Program Coordinator
A14: =MAX($A$1:A13)+1 -> 13 | C14: sadad | D14: wedfwef

Sheet wp_nds_rooms
A1: id | B1: code | C1: name | D1: type | E1: capacity | F1: location | G1: equipment | H1: amenities | I1: is_active | J1: created_at | K1: updated_at
A2: =IF(B2="", "", MAX($A$1:A1)+1) -> 1 | B2: HALL-001 | C2: Main Hall | D2: hall | E2: 200 | F2: Ground Floor | G2: Projector, Sound System, Stage | H2: Air Conditioning, WiFi | I2: 1 | J2: 46043.813 | K2: 46043.813
A3: =IF(B3="", "", MAX($A$1:A2)+1) -> 2 | B3: CLASS-001 | C3: Classroom 1 | D3: classroom | E3: 30 | F3: First Floor | G3: Whiteboard, Projector | H3: Air Conditioning | I3: 1 | J3: 46043.813 | K3: 46043.813
A4: =IF(B4="", "", MAX($A$1:A3)+1) -> 3 | B4: CLASS-002 | C4: Classroom 2 | D4: classroom | E4: 30 | F4: First Floor | G4: Whiteboard, Projector | H4: Air Conditioning | I4: 1 | J4: 46043.813 | K4: 46043.813
A5: =IF(B5="", "", MAX($A$1:A4)+1) -> 4 | B5: CLASS-003 | C5: Classroom 3 | D5: classroom | E5: 25 | F5: Second Floor | G5: Whiteboard, Projector | H5: Air Conditioning | I5: 1 | J5: 46043.813 | K5: 46043.813
A6: =IF(B6="", "", MAX($A$1:A5)+1) -> 5 | B6: KITCHEN-001 | C6: Kitchen 1 - Main Training Kitchen | D6: kitchen | E6: 20 | F6: Ground Floor | G6: Commercial Ovens, Stovetops, Prep Stations, Refrigeration | H6: Ventilation System, Safety Equipment | I6: 1 | J6: 46043.813 | K6: 46043.813
A7: =IF(B7="", "", MAX($A$1:A6)+1) -> 6 | B7: KITCHEN-002 | C7: Kitchen 2 - Pastry Lab | D7: kitchen | E7: 15 | F7: Ground Floor | G7: Pastry Equipment, Mixers, Ovens, Chilling Units | H7: Ventilation System, Safety Equipment | I7: 1 | J7: 46043.813 | K7: 46043.813
A8: =IF(B8="", "", MAX($A$1:A7)+1) -> 7 | B8: KITCHEN-003 | C8: Kitchen 3 - Advanced Techniques | D8: kitchen | E8: 18 | F8: Ground Floor | G8: Sous Vide, Smokers, Specialty Equipment | H8: Ventilation System, Safety Equipment | I8: 1 | J8: 46043.813 | K8: 46043.813
A9: =IF(B9="", "", MAX($A$1:A8)+1) -> 8 | B9: KITCHEN-004 | C9: Kitchen 4 - Butchery & Prep | D9: kitchen | E9: 12 | F9: Ground Floor | G9: Butchery Equipment, Prep Tables, Cold Storage | H9: Ventilation System, Safety Equipment | I9: 1 | J9: 46043.813 | K9: 46043.813

Sheet Accreditation_Bodies
A1: id | B1: name | C1: short_name | D1: description | E1: website_url | F1: contact_email | G1: status
A2: =MAX($A$1:A1)+1 -> 1 | B2: QCTO | G2: active
A3: =MAX($A$1:A2)+1 -> 2 | B3: CATHSETA
A4: =MAX($A$1:A3)+1 -> 3 | B4: International

Sheet Course_Accreditations
A1: id | B1: course_name_ignore | C1: course_id | D1: accreditation_body_id | E1: accreditation_number | F1: accreditation_date | G1: expiry_date | H1: status | I1: Column1
A2: =MAX($A$1:A1)+1 -> 1 | B2: Diploma in Introduction to the Hospitality Industry | C2: =IF($B2="", "", _xlfn.XLOOKUP($B2, 'Courses'!F:F, 'Courses'!A:A)) -> 1 | D2: 1 | E2: 1 | I2: active
A3: =MAX($A$1:A2)+1 -> 2 | B3: Advanced Diploma in Culinary Arts and Supervision | C3: =IF($B3="", "", _xlfn.XLOOKUP($B3, 'Courses'!F:F, 'Courses'!A:A)) -> 2 | D3: 2 | E3: 1 | I3: active
A4: =MAX($A$1:A3)+1 -> 3 | B4: Diploma Patisserie and Confectionery | C4: =IF($B4="", "", _xlfn.XLOOKUP($B4, 'Courses'!F:F, 'Courses'!A:A)) -> 3 | D4: 3 | E4: 1 | I4: active
A5: =MAX($A$1:A4)+1 -> 4 | B5: Diploma Food and Beverage Service | C5: =IF($B5="", "", _xlfn.XLOOKUP($B5, 'Courses'!F:F, 'Courses'!A:A)) -> 4 | D5: 4 | E5: 1 | I5: active
A6: =MAX($A$1:A5)+1 -> 5 | B6: Diploma in Housekeeping Service | C6: =IF($B6="", "", _xlfn.XLOOKUP($B6, 'Courses'!F:F, 'Courses'!A:A)) -> 5 | D6: 5 | E6: 1 | I6: active
A7: =MAX($A$1:A6)+1 -> 6 | B7: Advanced Diploma in Housekeeping Service | C7: =IF($B7="", "", _xlfn.XLOOKUP($B7, 'Courses'!F:F, 'Courses'!A:A)) -> 6 | D7: 6 | E7: 1 | I7: active
A8: =MAX($A$1:A7)+1 -> 7 | B8: Advanced Diploma in Barista | C8: =IF($B8="", "", _xlfn.XLOOKUP($B8, 'Courses'!F:F, 'Courses'!A:A)) -> 7 | D8: 7 | E8: 1 | I8: active
A9: =MAX($A$1:A8)+1 -> 8 | B9: Basic Cooking Course | C9: =IF($B9="", "", _xlfn.XLOOKUP($B9, 'Courses'!F:F, 'Courses'!A:A)) -> 8 | D9: 15 | E9: 1 | I9: active

Sheet Program_Types
A1: id | B1: name | C1: description | D1: typical_duration_years | E1: level
A2: 1 | B2: Diploma | D2: 1 | E2: undergraduate
A3: 2 | B3: Bachelor's Degree | D3: 3 | E3: undergraduate
A4: 3 | B4: Honours Degree | D4: 1 | E4: undergraduate
A5: 4 | B5: Master's Degree | D5: 2 | E5: postgraduate
A6: 5 | B6: Doctor of Philosophy | D6: 3 | E6: postgraduate
A7: 6 | B7: Certificate | D7: 0 | E7: professional
A8: 7 | B8: Short Course | D8: 0 | E8: professional

Sheet Course_Categories
A1: id | B1: name | C1: description
A2: 1 | B2: Core Course
A3: 2 | B3: Elective Course
A4: 3 | B4: Foundation Course
A5: 4 | B5: Capstone Project
A6: 5 | B6: Internship/Practicum

Sheet Students
A1: id | B1: student_number | C1: wp_user_id | D1: faculty_id | E1: first_name | F1: last_name | G1: email | H1: phone | I1: status
A2: 1 | B2: OCHEF0032G | D2: 5 | E2: Princess Rethabile | F2: Bakhetsi | G2: rethabileprincess3@gmail.com | H2: 656159454 | I2: active
A3: 2 | B3: OCHEF0033G | D3: 5 | E3: Hlalanathi | F3: Gala | G3: galahlalanathi@gmail.com | H3: 799236877 | I3: active
A4: 3 | B4: OCHEF0034G | D4: 5 | E4: Mbali Fortunate | F4: Gaveni | G4: mbaligaveni040@gmail.com | H4: 718607206 | I4: active
A5: 4 | B5: OCHEF0035G | D5: 5 | E5: Dieketseng | F5: Hlajoane | G5: dhlajoane03@gmail.com | H5: 661335476 | I5: active
A6: 5 | B6: OCHEF0036G | D6: 5 | E6: Danica Hay-Leigh | F6: Jansen | G6: jansendanica7@gmail.com | H6: 767860253 | I6: active
A7: 6 | B7: OCHEF0037G | D7: 5 | E7: Lebohang Ernest | F7: Kaba | G7: kabalebohang@gmail.com | H7: 676958403 | I7: active
A8: 7 | B8: OCHEF0038G | D8: 5 | E8: Ntombizodwa | F8: Khasi | G8: khasintombizodwa@gmail.com | H8: 678340751 | I8: active
A9: 8 | B9: OCHEF0039G | D9: 5 | E9: Retshidisitswe Romeo | F9: Mafa | G9: romeomafa10@icloud.com | H9: 623207310 | I9: active
A10: 9 | B10: OCHEF0040G | D10: 5 | E10: Ntsoaki | F10: Maqabe | G10: maqabentsoaki9@gmail.com | H10: 716317656 | I10: active
A11: 10 | B11: OCHEF0041G | D11: 5 | E11: Aphelele | F11: Matiwane | G11: aphelelematiwane28@gmail.com | H11: 787827037 | I11: active
A12: 11 | B12: OCHEF0042G | D12: 5 | E12: Zanele Nomasonto | F12: Mbele | G12: zanelembele94@gmail.com | H12: 797413115 | I12: active
A13: 12 | B13: OCHEF0043G | D13: 5 | E13: Itumeleng | F13: Mejoana | G13: mejoana.itu@student.nds.example | I13: active
A14: 13 | B14: OCHEF0044G | D14: 5 | E14: Sarah Dineo | F14: Minnie | G14: dineominnie9@gmail.com | H14: 685756008 | I14: active
A15: 14 | B15: OCHEF0045G | D15: 5 | E15: Olwethu | F15: Mkhwanazi | G15: omkhwanazi2111@gmail.com | H15: 694386773 | I15: active
A16: 15 | B16: OCHEF0046G | D16: 5 | E16: Samukele | F16: Mnguni | G16: samkelemnguni22@gmail.com | H16: 764580636 | I16: active
A17: 16 | B17: OCHEF0047G | D17: 5 | E17: Mapuleng | F17: Mokhema | G17: lebohangmokhema62@gmail.com | H17: 664162750 | I17: active
A18: 17 | B18: OCHEF0048G | D18: 5 | E18: Relebohile Motshidisi | F18: Morobe | G18: lebo9020@gmail.com | H18: 717689675 | I18: active
A19: 18 | B19: OCHEF0049G | D19: 5 | E19: Lerato | F19: Motloenya | G19: leratomotloenya13@gmail.com | H19: 698612970 | I19: active
A20: 19 | B20: OCHEF0050G | D20: 5 | E20: Neo Mankosasane | F20: Mpembe | G20: Khosieymakhosazanat@gmail.com | H20: 747979358 | I20: active
A21: 20 | B21: OCHEF0051G | D21: 5 | E21: Mpho Totius | F21: Mzizi | G21: Mphomzizi408@gmail.com | H21: 687095751 | I21: active
A22: 21 | B22: OCHEF0052G | D22: 5 | E22: Somila | F22: Ncaphayi | G22: ncaphayi.som@student.nds.example | I22: active
A23: 22 | B23: OCHEF0053G | D23: 5 | E23: Stefan Chris | F23: Nehring | G23: sc.nehring@gmail.com | H23: 763030549 | I23: active
A24: 23 | B24: OCHEF0054G | D24: 5 | E24: Andile Shaun | F24: Netnou | G24: netnou.and@student.nds.example | I24: active
A25: 24 | B25: OCHEF0055G | D25: 5 | E25: Rethabile Princess | F25: Pule | G25: princessbile111@gmail.com | H25: 684066481 | I25: active
A26: 25 | B26: OCHEF0056G | D26: 5 | E26: Hope Jabulile | F26: Radebe | G26: radebehope300@gmail.com | H26: 763037889 | I26: active
A27: 26 | B27: OCHEF0057G | D27: 5 | E27: Boitumelo | F27: Radebe | G27: radebe.boi@student.nds.example | I27: active
A28: 27 | B28: OCHEF0058G | D28: 5 | E28: Buhle | F28: Sobekwa | G28: buhlesobekwa@gmail.com | H28: 731541138 | I28: active
A29: 28 | B29: OCHEF0059G | D29: 5 | E29: Karabo | F29: Thonka | G29: thonkakarabo49@gmail.com | H29: 634345494 | I29: active
A30: 29 | B30: OCHEF0060G | D30: 5 | E30: Mamello Patience | F30: Tsekahali | G30: tsekahalimp@gmail.com | H30: 735468341 | I30: active
A31: 30 | B31: OCHEF0061G | D31: 5 | E31: Itumeleng Hessie | F31: Tsekahali | G31: tsekahaliituhe@gmail.com | H31: 791552961 | I31: active
A32: 31 | B32: OCHEF0001F | D32: 5 | E32: Felicia Nnedimma | F32: Alosiobi | G32: alisiobifelicia2@gmail.com | H32: 738201924 | I32: active
A33: 32 | B33: OCHEF0002F | D33: 5 | E33: Mbali | F33: Buthelezi | G33: buthelezimbali@gmail.com | H33: 764748608 | I33: active
A34: 33 | B34: OCHEF0003F | D34: 5 | E34: Eunice Fundokuhle | F34: Dlamini | G34: edhlamini98@gmail.com | H34: 810353895 | I34: active
A35: 34 | B35: OCHEF0004F | D35: 5 | E35: Siwamkele | F35: Fukuthwa | G35: siwamkele04@gmail.com | H35: 635337087 | I35: active
A36: 35 | B36: OCHEF0005F | D36: 5 | E36: Mamello | F36: Kumalo | G36: khumalomamello560@gmail.com | H36: 657455701 | I36: active
A37: 36 | B37: OCHEF0006F | D37: 5 | E37: Malefa | F37: Lebusa | G37: lebusa.mal@student.nds.example | I37: active
A38: 37 | B38: OCHEF0007F | D38: 5 | E38: Keorapetse | F38: Lehoko | G38: keorapetselehoko378@gmail.com | H38: 719400928 | I38: active
A39: 38 | B39: OCHEF0008F | D39: 5 | E39: Rethabile | F39: Lejone | G39: lejone.ret@student.nds.example | I39: active
A40: 39 | B40: OCHEF0009F | D40: 5 | E40: Rethabile | F40: Madumise | G40: retha751@gmail.com | H40: 663311224 | I40: active
...
